/glade/derecho/scratch/sturbeville/DPSCREAM_simulations/dpscream_rce_large_3km_default304k_branch/run/dpscream_rce_large_3km_default304k_branch_h0_last5days
Traceback (most recent call last):
  File "/glade/u/home/sturbeville/scmlib/DP_diagnostics/notebooks/large_domain/plot_mhist.py", line 27, in <module>
    ds = xr.open_dataset(file, chunks=chunks)[["T","CLDICE","NUMICE","Q"]]
  File "/glade/u/apps/opt/conda/envs/npl-2023a/lib/python3.9/site-packages/xarray/backends/api.py", line 525, in open_dataset
    engine = plugins.guess_engine(filename_or_obj)
  File "/glade/u/apps/opt/conda/envs/npl-2023a/lib/python3.9/site-packages/xarray/backends/plugins.py", line 177, in guess_engine
    raise ValueError(error_msg)
ValueError: did not find a match in any of xarray's currently installed IO backends ['netcdf4', 'h5netcdf', 'scipy', 'cfgrib', 'gini', 'pydap', 'zarr']. Consider explicitly selecting one of the installed engines via the ``engine`` parameter, or installing additional IO dependencies, see:
https://docs.xarray.dev/en/stable/getting-started-guide/installing.html
https://docs.xarray.dev/en/stable/user-guide/io.html
done
